<?xml version="1.0" ?>
<!-- =================================================================================== -->
<!-- |    This document was autogenerated by xacro from description.xacro              | -->
<!-- |    EDITING THIS FILE BY HAND IS NOT RECOMMENDED                                 | -->
<!-- =================================================================================== -->
<!--
Software License Agreement (BSD)

\file      description.urdf.xacro
\authors   Paul Bovbel <pbovbel@clearpathrobotics.com>, Devon Ash <dash@clearpathrobotics.com>
\copyright Copyright (c) 2015, Clearpath Robotics, Inc., All rights reserved.

Redistribution and use in source and binary forms, with or without modification, are permitted provided that
the following conditions are met:
 * Redistributions of source code must retain the above copyright notice, this list of conditions and the
   following disclaimer.
 * Redistributions in binary form must reproduce the above copyright notice, this list of conditions and the
   following disclaimer in the documentation and/or other materials provided with the distribution.
 * Neither the name of Clearpath Robotics nor the names of its contributors may be used to endorse or promote
   products derived from this software without specific prior written permission.

THIS SOFTWARE IS PROVIDED BY THE COPYRIGHT HOLDERS AND CONTRIBUTORS "AS IS" AND ANY EXPRESS OR IMPLIED WAR-
RANTIES, INCLUDING, BUT NOT LIMITED TO, THE IMPLIED WARRANTIES OF MERCHANTABILITY AND FITNESS FOR A PARTICULAR
PURPOSE ARE DISCLAIMED. IN NO EVENT SHALL THE COPYRIGHT HOLDER OR CONTRIBUTORS BE LIABLE FOR ANY DIRECT, IN-
DIRECT, INCIDENTAL, SPECIAL, EXEMPLARY, OR CONSEQUENTIAL DAMAGES (INCLUDING, BUT NOT LIMITED TO, PROCUREMENT
OF SUBSTITUTE GOODS OR SERVICES; LOSS OF USE, DATA, OR PROFITS; OR BUSINESS INTERRUPTION) HOWEVER CAUSED AND
ON ANY THEORY OF LIABILITY, WHETHER IN CONTRACT, STRICT LIABILITY, OR TORT (INCLUDING NEGLIGENCE OR OTHERWISE)
ARISING IN ANY WAY OUT OF THE USE OF THIS SOFTWARE, EVEN IF ADVISED OF THE POSSIBILITY OF SUCH DAMAGE.
-->
<robot name="husky" xmlns:xacro="http://www.ros.org/wiki/xacro">
  <!-- Included URDF/XACRO Files -->
  <!-- Inertia parameters -->
  <!-- This mass might be incorrect -->
  <!-- Kinematic model -->
  <!-- Properties from urcontrol.conf -->
  <!--
    DH for UR5:
    a = [0.00000, -0.42500, -0.39225,  0.00000,  0.00000,  0.0000]
    d = [0.089159,  0.00000,  0.00000,  0.10915,  0.09465,  0.0823]
    alpha = [ 1.570796327, 0, 0, 1.570796327, -1.570796327, 0 ]
    q_home_offset = [0, -1.570796327, 0, -1.570796327, 0, 0]
    joint_direction = [-1, -1, 1, 1, 1, 1]
    mass = [3.7000, 8.3930, 2.2750, 1.2190, 1.2190, 0.1879]
    center_of_mass = [ [0, -0.02561, 0.00193], [0.2125, 0, 0.11336], [0.11993, 0.0, 0.0265], [0, -0.0018, 0.01634], [0, 0.0018,0.01634], [0, 0, -0.001159] ]
  -->
  <!-- Arbitrary offsets for shoulder/elbow joints -->
  <!-- measured from model -->
  <!-- measured from model -->
  <!-- link lengths used in model -->
  <!--property name="shoulder_height" value="0.089159" /-->
  <!--property name="shoulder_offset" value="0.13585" /-->
  <!-- shoulder_offset - elbow_offset + wrist_1_length = 0.10915 -->
  <!--property name="upper_arm_length" value="0.42500" /-->
  <!--property name="elbow_offset" value="0.1197" /-->
  <!-- CAD measured -->
  <!--property name="forearm_length" value="0.39225" /-->
  <!--property name="wrist_1_length" value="0.093" /-->
  <!-- CAD measured -->
  <!--property name="wrist_2_length" value="0.09465" /-->
  <!-- In CAD this distance is 0.930, but in the spec it is 0.09465 -->
  <!--property name="wrist_3_length" value="0.0823" /-->
  <!-- manually measured -->
  <!-- manually measured -->
  <!-- manually measured -->
  <!-- manually measured -->
  <!-- manually measured -->
  <!-- Base Size -->
  <!-- Wheel Mounting Positions -->
  <!-- Wheel Properties -->
  <!-- POWERCUBES -->
  <!-- Angle connector -->
  <link name="angle_connector">
    <inertial>
      <mass value="0.0001"/>
      <origin xyz="0 0 0"/>
      <inertia ixx="0.0001" ixy="0.0" ixz="0.0" iyy="0.0001" iyz="0.0" izz="0.0001"/>
    </inertial>
    <visual>
      <origin rpy="0 0 0" xyz="0 0 0"/>
      <geometry>
        <mesh filename="file:///home/mike/catkin_ws/src/wrock_husky_description/meshes/Bracket.stl" scale="0.001 0.001 0.001"/>
      </geometry>
      <material name="DarkPCubeGrey">
        <color rgba=".1 .1 .1 1"/>
      </material>
    </visual>
  </link>
  <joint name="base_cube_joint" type="fixed">
    <origin rpy="0.698132 0 1.570795" xyz="0.405857 0.147637 0.256414"/>
    <parent link="base_footprint"/>
    <child link="angle_connector"/>
  </joint>
  <!-- FIXED-CUBE-5 -->
  <link name="fixed_cube_5">
    <inertial>
      <mass value="0.0001"/>
      <origin xyz="0 0 0"/>
      <inertia ixx="0.0001" ixy="0.0" ixz="0.0" iyy="0.0001" iyz="0.0" izz="0.0001"/>
    </inertial>
    <visual>
      <origin rpy="0 0 0" xyz="-.035 -.035 -.035"/>
      <geometry>
        <box size="0.07 0.07 0.07"/>
      </geometry>
      <material name="PCubeGrey">
        <color rgba=".2 .2 .2 1"/>
      </material>
    </visual>
  </link>
  <joint name="fixed_cube_5_joint" type="fixed">
    <origin rpy="-0.698132 0 0" xyz="0.047625 0.231527766824 0.128181623232"/>
    <parent link="angle_connector"/>
    <child link="fixed_cube_5"/>
  </joint>
  <!-- CUBE-5 -->
  <link name="cube_5">
    <inertial>
      <mass value="0.0001"/>
      <origin xyz="0 0 0"/>
      <inertia ixx="0.0001" ixy="0.0" ixz="0.0" iyy="0.0001" iyz="0.0" izz="0.0001"/>
    </inertial>
    <visual>
      <origin rpy="0 0 0" xyz="0 0 0"/>
      <geometry>
        <box size="0.07 0.07 0.07"/>
      </geometry>
      <material name="PCubeGrey">
        <color rgba=".2 .2 .2 1"/>
      </material>
    </visual>
  </link>
  <joint name="cube_joint" type="continuous">
    <origin rpy="-1.570795 0 0" xyz="-.035 -.105 -.035"/>
    <axis xyz="0 0 -1 "/>
    <parent link="fixed_cube_5"/>
    <child link="cube_5"/>
  </joint>
  <!-- End Effector -->
  <!-- LASER payload (by default, a SICK LMS111). -->
  <link name="laser">
    <visual>
      <origin rpy="0 0 1.570795" xyz="0 0 0"/>
      <geometry>
        <!-- Origin of this mesh is the base of the bracket. -${M_PI/2}-->
        <mesh filename="file:///home/mike/catkin_ws/src/wrock_husky_description/meshes/laser.stl" scale="0.001 0.001 0.001"/>
      </geometry>
      <material name="white">
        <color rgba="1 1 1 1"/>
      </material>
    </visual>
  </link>
  <joint name="laser_mount_joint" type="fixed">
    <!--<origin xyz="${.019663 - .035} ${-.035 - .05974} -.027623" rpy="${M_PI/2} 0 ${-M_PI/2}" />-->
    <origin rpy="1.570795 0 -1.570795" xyz="-0.00796 -0.09474 -.027623"/>
    <parent link="cube_5"/>
    <child link="laser"/>
  </joint>
  <link name="BASE">
    <visual>
      <origin rpy="1.570795 0 0" xyz="0 0 0"/>
      <geometry>
        <mesh filename="file:///home/mike/catkin_ws/src/wrock/vs060/model/meshes/j1.stl" scale="0.001 0.001 0.001">
         </mesh>
      </geometry>
      <material name="blue">
        <color rgba="0 0 .8 1"/>
      </material>
    </visual>
    <collision>
      <origin rpy="1.570795 0 0" xyz="0 0 0"/>
      <geometry>
        <mesh filename="file:///home/mike/catkin_ws/src/wrock/vs060/model/meshes/j1.stl" scale="0.001 0.001 0.001">
         </mesh>
      </geometry>
    </collision>
    <inertial>
      <mass value="1000"/>
      <origin rpy="0 -0 0" xyz="0 0 0"/>
      <inertia ixx="20" ixy="0" ixz="0" iyy="20" iyz="0" izz="20"/>
    </inertial>
  </link>
  <link name="J1">
    <visual>
      <origin rpy="1.570795 0 0" xyz="0 0 0"/>
      <geometry>
        <mesh filename="file:///home/mike/catkin_ws/src/wrock/vs060/model/meshes/j2.stl" scale="0.001 0.001 0.001"/>
      </geometry>
      <material name="white">
        <color rgba="1 1 1 1"/>
      </material>
    </visual>
    <collision>
      <origin rpy="1.570795 0 0" xyz="0 0 0"/>
      <geometry>
        <mesh filename="file:///home/mike/catkin_ws/src/wrock/vs060/model/meshes/j2.stl" scale="0.001 0.001 0.001"/>
      </geometry>
    </collision>
    <inertial>
      <mass value="4.327"/>
      <origin rpy="0 -0 0" xyz="0.013885 -0.005997 0.043991"/>
      <inertia ixx="0.025492" ixy="0" ixz="0" iyy="0.032502" iyz="-3.26672e-18" izz="0.01779"/>
    </inertial>
  </link>
  <link name="J2">
    <visual>
      <origin rpy="1.570795 0 0" xyz="0 0 0"/>
      <geometry>
        <mesh filename="file:///home/mike/catkin_ws/src/wrock/vs060/model/meshes/j3.stl" scale="0.001 0.001 0.001"/>
      </geometry>
      <material name="white"/>
    </visual>
    <collision>
      <origin rpy="1.570795 0 0" xyz="0 0 0"/>
      <geometry>
        <mesh filename="file:///home/mike/catkin_ws/src/wrock/vs060/model/meshes/j3.stl" scale="0.001 0.001 0.001"/>
      </geometry>
    </collision>
    <inertial>
      <mass value="9.475"/>
      <origin rpy="1.570795 0 0" xyz="0 0 0"/>
      <inertia ixx="0.108024" ixy="0" ixz="0" iyy="0.025579" iyz="1.93827e-17" izz="0.112871"/>
    </inertial>
  </link>
  <link name="J3">
    <visual>
      <origin rpy="1.570795 0 0" xyz="0 0 0"/>
      <geometry>
        <mesh filename="file:///home/mike/catkin_ws/src/wrock/vs060/model/meshes/j4.stl" scale="0.001 0.001 0.001"/>
      </geometry>
      <material name="white"/>
    </visual>
    <collision>
      <origin rpy="1.570795 0 0" xyz="0 0 0"/>
      <geometry>
        <mesh filename="file:///home/mike/catkin_ws/src/wrock/vs060/model/meshes/j4.stl" scale="0.001 0.001 0.001"/>
      </geometry>
    </collision>
    <inertial>
      <mass value="4.097"/>
      <origin rpy="1.570795 -0 0" xyz="0.011544 -0.057408 0.006203"/>
      <inertia ixx="0.015999" ixy="0" ixz="0" iyy="0.00638" iyz="2.33191e-18" izz="0.016882"/>
    </inertial>
  </link>
  <link name="J4">
    <visual>
      <origin rpy="1.570795 0 0" xyz="0 0 0"/>
      <geometry>
        <mesh filename="file:///home/mike/catkin_ws/src/wrock/vs060/model/meshes/j5.stl" scale="0.001 0.001 0.001"/>
      </geometry>
      <material name="white"/>
    </visual>
    <collision>
      <origin rpy="1.570795 0 0" xyz="0 0 0"/>
      <geometry>
        <mesh filename="file:///home/mike/catkin_ws/src/wrock/vs060/model/meshes/j5.stl" scale="0.001 0.001 0.001"/>
      </geometry>
    </collision>
    <inertial>
      <mass value="1.779"/>
      <origin rpy="1.570795 0 0" xyz="0 0 0"/>
      <inertia ixx="0.005106" ixy="0" ixz="0" iyy="0.005266" iyz="-5.87308e-19" izz="0.002621"/>
    </inertial>
  </link>
  <link name="J5">
    <visual>
      <origin rpy="1.570795 0 0" xyz="0 0 0"/>
      <geometry>
        <mesh filename="file:///home/mike/catkin_ws/src/wrock/vs060/model/meshes/j6.stl" scale="0.001 0.001 0.001"/>
      </geometry>
      <material name="white"/>
    </visual>
    <collision>
      <origin rpy="1.570795 0 0" xyz="0 0 0"/>
      <geometry>
        <mesh filename="file:///home/mike/catkin_ws/src/wrock/vs060/model/meshes/j6.stl" scale="0.001 0.001 0.001"/>
      </geometry>
    </collision>
    <inertial>
      <mass value="1.211"/>
      <origin rpy="1.570795 -0 0" xyz="0.011902 -0.004739 0.010398"/>
      <inertia ixx="0.001093" ixy="0" ixz="0" iyy="0.001629" iyz="-3.10862e-21" izz="0.001615"/>
    </inertial>
  </link>
  <joint name="j1" type="continuous">
    <parent link="BASE"/>
    <child link="J1"/>
    <origin rpy="0 -0 0 " xyz="0 0 0.155"/>
    <axis xyz="0 0 1"/>
    <!-- <limit lower="-2.96706" upper="2.96706" effort="19.7336" velocity="0.5" /> -->
  </joint>
  <joint name="j2" type="continuous">
    <parent link="J1"/>
    <child link="J2"/>
    <origin rpy="0 -0 0 " xyz="0 0 0.125"/>
    <axis xyz="0 1 0"/>
  </joint>
  <joint name="j3" type="continuous">
    <parent link="J2"/>
    <child link="J3"/>
    <origin rpy="0 -0 0 " xyz="0 0 .210"/>
    <axis xyz="0 1 0"/>
  </joint>
  <joint name="j4" type="continuous">
    <parent link="J3"/>
    <child link="J4"/>
    <origin rpy="0 -0 0 " xyz="-.083 0 .075"/>
    <axis xyz="1 0 0"/>
  </joint>
  <joint name="j5" type="continuous">
    <parent link="J4"/>
    <child link="J5"/>
    <origin rpy="0 -0 0 " xyz="-.127 0 0"/>
    <axis xyz="0 1 0"/>
  </joint>
  <joint name="Arm_Mount" type="fixed">
    <origin rpy="0 0 3.14159" xyz=".156971 -.096013 .405369"/>
    <parent link="base_footprint"/>
    <child link="BASE"/>
  </joint>
  <!-- Base link is the center of the robot's bottom plate -->
  <link name="base_link">
    <visual>
      <origin rpy="0 0 0" xyz="0 0 0"/>
      <geometry>
        <mesh filename="package://husky_description/meshes/base_link.dae"/>
      </geometry>
    </visual>
    <collision>
      <origin rpy="0 0 0" xyz="0 0 0.061875"/>
      <geometry>
        <box size="0.9874 0.5709 0.12375"/>
      </geometry>
    </collision>
    <collision>
      <origin rpy="0 0 0" xyz="0 0 0.185625"/>
      <geometry>
        <box size="0.78992 0.5709 0.12375"/>
      </geometry>
    </collision>
  </link>
  <!-- Base footprint is on the ground under the robot -->
  <link name="base_footprint"/>
  <joint name="base_footprint_joint" type="fixed">
    <origin rpy="0 0 0" xyz="0 0 -0.14493"/>
    <parent link="base_link"/>
    <child link="base_footprint"/>
  </joint>
  <!-- Interial link stores the robot's inertial information -->
  <link name="inertial_link">
    <inertial>
      <mass value="33.455"/>
      <origin xyz="-0.08748 -0.00085 0.09947"/>
      <inertia ixx="0.6022" ixy="-0.02364" ixz="-0.1197" iyy="1.7386" iyz="-0.001544" izz="2.0296"/>
    </inertial>
  </link>
  <joint name="inertial_joint" type="fixed">
    <origin rpy="0 0 0" xyz="0 0 0"/>
    <parent link="base_link"/>
    <child link="inertial_link"/>
  </joint>
  <!-- IMU Link is the standard mounting position for the UM6 IMU.-->
  <!-- Can be modified with environment variables in /etc/ros/setup.bash -->
  <link name="imu_link"/>
  <joint name="imu_joint" type="fixed">
    <origin rpy="0 -1.5708 3.1416" xyz="0.19 0 0.149"/>
    <parent link="base_link"/>
    <child link="imu_link"/>
  </joint>
  <gazebo reference="imu_link">
    </gazebo>
  <!-- Husky wheel macros -->
  <link name="front_left_wheel_link">
    <inertial>
      <mass value="2.637"/>
      <origin xyz="0 0 0"/>
      <inertia ixx="0.02467" ixy="0" ixz="0" iyy="0.02467" iyz="0" izz="0.04411"/>
    </inertial>
    <visual>
      <origin rpy="0 0 0" xyz="0 0 0"/>
      <geometry>
        <mesh filename="package://husky_description/meshes/wheel.dae"/>
      </geometry>
    </visual>
    <collision>
      <origin rpy="1.570795 0 0" xyz="0 0 0"/>
      <geometry>
        <cylinder length="0.1143" radius="0.17775"/>
      </geometry>
    </collision>
  </link>
  <gazebo reference="front_left_wheel_link">
    <mu1 value="1.0"/>
    <mu2 value="1.0"/>
    <kp value="10000000.0"/>
    <kd value="1.0"/>
    <fdir1 value="1 0 0"/>
  </gazebo>
  <joint name="front_left_wheel" type="continuous">
    <parent link="base_link"/>
    <child link="front_left_wheel_link"/>
    <origin rpy="0 0 0" xyz="0.256 0.2854 0.03282"/>
    <axis rpy="0 0 0" xyz="0 1 0"/>
  </joint>
  <transmission name="front_left_wheel_trans" type="SimpleTransmission">
    <type>transmission_interface/SimpleTransmission</type>
    <actuator name="front_left_wheel_motor">
      <mechanicalReduction>1</mechanicalReduction>
    </actuator>
    <joint name="front_left_wheel">
      <hardwareInterface>VelocityJointInterface</hardwareInterface>
    </joint>
  </transmission>
  <link name="front_right_wheel_link">
    <inertial>
      <mass value="2.637"/>
      <origin xyz="0 0 0"/>
      <inertia ixx="0.02467" ixy="0" ixz="0" iyy="0.02467" iyz="0" izz="0.04411"/>
    </inertial>
    <visual>
      <origin rpy="0 0 0" xyz="0 0 0"/>
      <geometry>
        <mesh filename="package://husky_description/meshes/wheel.dae"/>
      </geometry>
    </visual>
    <collision>
      <origin rpy="1.570795 0 0" xyz="0 0 0"/>
      <geometry>
        <cylinder length="0.1143" radius="0.17775"/>
      </geometry>
    </collision>
  </link>
  <gazebo reference="front_right_wheel_link">
    <mu1 value="1.0"/>
    <mu2 value="1.0"/>
    <kp value="10000000.0"/>
    <kd value="1.0"/>
    <fdir1 value="1 0 0"/>
  </gazebo>
  <joint name="front_right_wheel" type="continuous">
    <parent link="base_link"/>
    <child link="front_right_wheel_link"/>
    <origin rpy="0 0 0" xyz="0.256 -0.2854 0.03282"/>
    <axis rpy="0 0 0" xyz="0 1 0"/>
  </joint>
  <transmission name="front_right_wheel_trans" type="SimpleTransmission">
    <type>transmission_interface/SimpleTransmission</type>
    <actuator name="front_right_wheel_motor">
      <mechanicalReduction>1</mechanicalReduction>
    </actuator>
    <joint name="front_right_wheel">
      <hardwareInterface>VelocityJointInterface</hardwareInterface>
    </joint>
  </transmission>
  <link name="rear_left_wheel_link">
    <inertial>
      <mass value="2.637"/>
      <origin xyz="0 0 0"/>
      <inertia ixx="0.02467" ixy="0" ixz="0" iyy="0.02467" iyz="0" izz="0.04411"/>
    </inertial>
    <visual>
      <origin rpy="0 0 0" xyz="0 0 0"/>
      <geometry>
        <mesh filename="package://husky_description/meshes/wheel.dae"/>
      </geometry>
    </visual>
    <collision>
      <origin rpy="1.570795 0 0" xyz="0 0 0"/>
      <geometry>
        <cylinder length="0.1143" radius="0.17775"/>
      </geometry>
    </collision>
  </link>
  <gazebo reference="rear_left_wheel_link">
    <mu1 value="1.0"/>
    <mu2 value="1.0"/>
    <kp value="10000000.0"/>
    <kd value="1.0"/>
    <fdir1 value="1 0 0"/>
  </gazebo>
  <joint name="rear_left_wheel" type="continuous">
    <parent link="base_link"/>
    <child link="rear_left_wheel_link"/>
    <origin rpy="0 0 0" xyz="-0.256 0.2854 0.03282"/>
    <axis rpy="0 0 0" xyz="0 1 0"/>
  </joint>
  <transmission name="rear_left_wheel_trans" type="SimpleTransmission">
    <type>transmission_interface/SimpleTransmission</type>
    <actuator name="rear_left_wheel_motor">
      <mechanicalReduction>1</mechanicalReduction>
    </actuator>
    <joint name="rear_left_wheel">
      <hardwareInterface>VelocityJointInterface</hardwareInterface>
    </joint>
  </transmission>
  <link name="rear_right_wheel_link">
    <inertial>
      <mass value="2.637"/>
      <origin xyz="0 0 0"/>
      <inertia ixx="0.02467" ixy="0" ixz="0" iyy="0.02467" iyz="0" izz="0.04411"/>
    </inertial>
    <visual>
      <origin rpy="0 0 0" xyz="0 0 0"/>
      <geometry>
        <mesh filename="package://husky_description/meshes/wheel.dae"/>
      </geometry>
    </visual>
    <collision>
      <origin rpy="1.570795 0 0" xyz="0 0 0"/>
      <geometry>
        <cylinder length="0.1143" radius="0.17775"/>
      </geometry>
    </collision>
  </link>
  <gazebo reference="rear_right_wheel_link">
    <mu1 value="1.0"/>
    <mu2 value="1.0"/>
    <kp value="10000000.0"/>
    <kd value="1.0"/>
    <fdir1 value="1 0 0"/>
  </gazebo>
  <joint name="rear_right_wheel" type="continuous">
    <parent link="base_link"/>
    <child link="rear_right_wheel_link"/>
    <origin rpy="0 0 0" xyz="-0.256 -0.2854 0.03282"/>
    <axis rpy="0 0 0" xyz="0 1 0"/>
  </joint>
  <transmission name="rear_right_wheel_trans" type="SimpleTransmission">
    <type>transmission_interface/SimpleTransmission</type>
    <actuator name="rear_right_wheel_motor">
      <mechanicalReduction>1</mechanicalReduction>
    </actuator>
    <joint name="rear_right_wheel">
      <hardwareInterface>VelocityJointInterface</hardwareInterface>
    </joint>
  </transmission>
  <!-- Spawn Husky chassis -->
  <link name="top_chassis_link">
    <visual>
      <origin rpy="0 0 0" xyz="0 0 0"/>
      <geometry>
        <mesh filename="package://husky_description/meshes/top_chassis.dae"/>
      </geometry>
    </visual>
  </link>
  <!-- Attach chassis to the robot -->
  <joint name="top_chassis_joint" type="fixed">
    <parent link="base_link"/>
    <child link="top_chassis_link"/>
  </joint>
  <!-- Spawn user rails -->
  <link name="user_rail_link">
    <visual>
      <geometry>
        <mesh filename="package://husky_description/meshes/user_rail.dae"/>
      </geometry>
    </visual>
  </link>
  <!-- Attach user rails to base link -->
  <joint name="user_rail" type="fixed">
    <origin rpy="0 0 0" xyz="0.272 0 0.245"/>
    <parent link="base_link"/>
    <child link="user_rail_link"/>
  </joint>
  <!-- Spawn front bumper link -->
  <link name="front_bumper_link">
    <visual>
      <geometry>
        <mesh filename="package://husky_description/meshes/bumper.dae"/>
      </geometry>
    </visual>
  </link>
  <!-- Attach front bumper -->
  <joint name="front_bumper" type="fixed">
    <origin rpy="0 0 0" xyz="0.48 0 0.091"/>
    <parent link="base_link"/>
    <child link="front_bumper_link"/>
  </joint>
  <!-- Spawn rear bumper link -->
  <link name="rear_bumper_link">
    <visual>
      <geometry>
        <mesh filename="package://husky_description/meshes/bumper.dae"/>
      </geometry>
    </visual>
  </link>
  <!-- Attach rear bumper -->
  <joint name="rear_bumper" type="fixed">
    <origin rpy="0 0 3.14159" xyz="-0.48 0 0.091"/>
    <parent link="base_link"/>
    <child link="rear_bumper_link"/>
  </joint>
  <!-- Spawn the top plate -->
  <link name="top_plate_link">
    <visual>
      <origin rpy="0 0 0" xyz="0 0 0"/>
      <geometry>
        <mesh filename="package://husky_description/meshes/top_plate.dae"/>
      </geometry>
    </visual>
    <collision>
      <origin rpy="0 0 0" xyz="0 0 0"/>
      <geometry>
        <mesh filename="package://husky_description/meshes/top_plate.dae"/>
      </geometry>
    </collision>
    <collision>
      <!-- Extra collision tag for widgets on top plate -->
      <geometry>
        <box rpy="0 0 0" size="0.32 0.41 0.09"/>
      </geometry>
    </collision>
  </link>
  <!-- Attach top plate -->
  <joint name="top_plate_joint" type="fixed">
    <parent link="base_link"/>
    <child link="top_plate_link"/>
    <origin rpy="0 0 0" xyz="0.0812 0 0.245"/>
  </joint>
</robot>
